[2024-02-22T08:39:04.644+0000] {scheduler_job_runner.py:1586} WARNING - Marking task instance <TaskInstance: primeira_dag.tsk1 manual__2024-02-21T09:56:00.718346+00:00 [queued]> stuck in queued as failed. If the task instance has available retries, it will be retried.
[2024-02-22T08:39:06.870+0000] {scheduler_job_runner.py:781} ERROR - Executor reports task instance <TaskInstance: primeira_dag.tsk1 manual__2024-02-21T09:56:00.718346+00:00 [queued]> finished (failed) although the task says it's queued. (Info: None) Was the task killed externally?
