[2024-02-28 08:59:05,066] {taskinstance.py:903} INFO - Dependencies all met for <TaskInstance: email_teste.tsk4 2024-02-28T08:58:57.488679+00:00 [queued]>
[2024-02-28 08:59:05,117] {taskinstance.py:903} INFO - Dependencies all met for <TaskInstance: email_teste.tsk4 2024-02-28T08:58:57.488679+00:00 [queued]>
[2024-02-28 08:59:05,118] {taskinstance.py:1095} INFO - 
--------------------------------------------------------------------------------
[2024-02-28 08:59:05,118] {taskinstance.py:1096} INFO - Starting attempt 1 of 2
[2024-02-28 08:59:05,118] {taskinstance.py:1097} INFO - 
--------------------------------------------------------------------------------
[2024-02-28 08:59:05,137] {taskinstance.py:1115} INFO - Executing <Task(BashOperator): tsk4> on 2024-02-28T08:58:57.488679+00:00
[2024-02-28 08:59:05,149] {standard_task_runner.py:76} INFO - Running: ['***', 'tasks', 'run', 'email_teste', 'tsk4', '2024-02-28T08:58:57.488679+00:00', '--job-id', '138', '--pool', 'default_pool', '--raw', '--subdir', 'DAGS_FOLDER/email.py', '--cfg-path', '/tmp/tmpy5tqv39o', '--error-file', '/tmp/tmpg5ccf8g8']
[2024-02-28 08:59:05,144] {standard_task_runner.py:52} INFO - Started process 88 to run task
[2024-02-28 08:59:05,150] {standard_task_runner.py:77} INFO - Job 138: Subtask tsk4
[2024-02-28 08:59:05,217] {logging_mixin.py:109} INFO - Running <TaskInstance: email_teste.tsk4 2024-02-28T08:58:57.488679+00:00 [running]> on host 14529f4830f2
[2024-02-28 08:59:05,302] {taskinstance.py:1254} INFO - Exporting the following env vars:
AIRFLOW_CTX_DAG_EMAIL=jezandre_tiago@hotmail.com
AIRFLOW_CTX_DAG_OWNER=***
AIRFLOW_CTX_DAG_ID=email_teste
AIRFLOW_CTX_TASK_ID=tsk4
AIRFLOW_CTX_EXECUTION_DATE=2024-02-28T08:58:57.488679+00:00
AIRFLOW_CTX_DAG_RUN_ID=manual__2024-02-28T08:58:57.488679+00:00
[2024-02-28 08:59:05,304] {subprocess.py:52} INFO - Tmp dir root location: 
 /tmp
[2024-02-28 08:59:05,306] {subprocess.py:63} INFO - Running command: ['bash', '-c', 'exit 1']
[2024-02-28 08:59:05,320] {subprocess.py:74} INFO - Output:
[2024-02-28 08:59:05,324] {subprocess.py:82} INFO - Command exited with return code 1
[2024-02-28 08:59:05,341] {taskinstance.py:1463} ERROR - Task failed with exception
Traceback (most recent call last):
  File "/home/airflow/.local/lib/python3.6/site-packages/airflow/models/taskinstance.py", line 1165, in _run_raw_task
    self._prepare_and_execute_task_with_callbacks(context, task)
  File "/home/airflow/.local/lib/python3.6/site-packages/airflow/models/taskinstance.py", line 1283, in _prepare_and_execute_task_with_callbacks
    result = self._execute_task(context, task_copy)
  File "/home/airflow/.local/lib/python3.6/site-packages/airflow/models/taskinstance.py", line 1313, in _execute_task
    result = task_copy.execute(context=context)
  File "/home/airflow/.local/lib/python3.6/site-packages/airflow/operators/bash.py", line 176, in execute
    raise AirflowException('Bash command failed. The command returned a non-zero exit code.')
airflow.exceptions.AirflowException: Bash command failed. The command returned a non-zero exit code.
[2024-02-28 08:59:05,345] {taskinstance.py:1513} INFO - Marking task as UP_FOR_RETRY. dag_id=email_teste, task_id=tsk4, execution_date=20240228T085857, start_date=20240228T085905, end_date=20240228T085905
[2024-02-28 08:59:05,405] {local_task_job.py:151} INFO - Task exited with return code 1
[2024-02-28 08:59:05,458] {local_task_job.py:261} INFO - 0 downstream tasks scheduled from follow-on schedule check
