[2024-02-28 09:10:04,304] {taskinstance.py:903} INFO - Dependencies all met for <TaskInstance: email_teste.tsk4 2024-02-28T09:09:55.892866+00:00 [queued]>
[2024-02-28 09:10:04,338] {taskinstance.py:903} INFO - Dependencies all met for <TaskInstance: email_teste.tsk4 2024-02-28T09:09:55.892866+00:00 [queued]>
[2024-02-28 09:10:04,339] {taskinstance.py:1095} INFO - 
--------------------------------------------------------------------------------
[2024-02-28 09:10:04,339] {taskinstance.py:1096} INFO - Starting attempt 1 of 2
[2024-02-28 09:10:04,339] {taskinstance.py:1097} INFO - 
--------------------------------------------------------------------------------
[2024-02-28 09:10:04,372] {taskinstance.py:1115} INFO - Executing <Task(BashOperator): tsk4> on 2024-02-28T09:09:55.892866+00:00
[2024-02-28 09:10:04,381] {standard_task_runner.py:52} INFO - Started process 68 to run task
[2024-02-28 09:10:04,389] {standard_task_runner.py:76} INFO - Running: ['***', 'tasks', 'run', 'email_teste', 'tsk4', '2024-02-28T09:09:55.892866+00:00', '--job-id', '156', '--pool', 'default_pool', '--raw', '--subdir', 'DAGS_FOLDER/email.py', '--cfg-path', '/tmp/tmphqbd33qm', '--error-file', '/tmp/tmpzh_xc15c']
[2024-02-28 09:10:04,390] {standard_task_runner.py:77} INFO - Job 156: Subtask tsk4
[2024-02-28 09:10:04,478] {logging_mixin.py:109} INFO - Running <TaskInstance: email_teste.tsk4 2024-02-28T09:09:55.892866+00:00 [running]> on host 6c21db20f5ac
[2024-02-28 09:10:04,614] {taskinstance.py:1254} INFO - Exporting the following env vars:
AIRFLOW_CTX_DAG_EMAIL=jezandre_tiago@hotmail.com
AIRFLOW_CTX_DAG_OWNER=***
AIRFLOW_CTX_DAG_ID=email_teste
AIRFLOW_CTX_TASK_ID=tsk4
AIRFLOW_CTX_EXECUTION_DATE=2024-02-28T09:09:55.892866+00:00
AIRFLOW_CTX_DAG_RUN_ID=manual__2024-02-28T09:09:55.892866+00:00
[2024-02-28 09:10:04,616] {subprocess.py:52} INFO - Tmp dir root location: 
 /tmp
[2024-02-28 09:10:04,619] {subprocess.py:63} INFO - Running command: ['bash', '-c', 'exit 1']
[2024-02-28 09:10:04,653] {subprocess.py:74} INFO - Output:
[2024-02-28 09:10:04,659] {subprocess.py:82} INFO - Command exited with return code 1
[2024-02-28 09:10:04,706] {taskinstance.py:1463} ERROR - Task failed with exception
Traceback (most recent call last):
  File "/home/airflow/.local/lib/python3.6/site-packages/airflow/models/taskinstance.py", line 1165, in _run_raw_task
    self._prepare_and_execute_task_with_callbacks(context, task)
  File "/home/airflow/.local/lib/python3.6/site-packages/airflow/models/taskinstance.py", line 1283, in _prepare_and_execute_task_with_callbacks
    result = self._execute_task(context, task_copy)
  File "/home/airflow/.local/lib/python3.6/site-packages/airflow/models/taskinstance.py", line 1313, in _execute_task
    result = task_copy.execute(context=context)
  File "/home/airflow/.local/lib/python3.6/site-packages/airflow/operators/bash.py", line 176, in execute
    raise AirflowException('Bash command failed. The command returned a non-zero exit code.')
airflow.exceptions.AirflowException: Bash command failed. The command returned a non-zero exit code.
[2024-02-28 09:10:04,713] {taskinstance.py:1513} INFO - Marking task as UP_FOR_RETRY. dag_id=email_teste, task_id=tsk4, execution_date=20240228T090955, start_date=20240228T091004, end_date=20240228T091004
[2024-02-28 09:10:04,894] {local_task_job.py:151} INFO - Task exited with return code 1
[2024-02-28 09:10:05,011] {local_task_job.py:261} INFO - 0 downstream tasks scheduled from follow-on schedule check
