[2024-02-22T08:39:04.759+0000] {scheduler_job_runner.py:1586} WARNING - Marking task instance <TaskInstance: segunda_dag.tsk1 manual__2024-02-21T10:00:25.374658+00:00 [queued]> stuck in queued as failed. If the task instance has available retries, it will be retried.
[2024-02-22T08:39:06.981+0000] {scheduler_job_runner.py:781} ERROR - Executor reports task instance <TaskInstance: segunda_dag.tsk1 manual__2024-02-21T10:00:25.374658+00:00 [queued]> finished (failed) although the task says it's queued. (Info: None) Was the task killed externally?
