[2024-02-28 09:30:55,394] {taskinstance.py:903} INFO - Dependencies all met for <TaskInstance: email_teste.send_email 2024-02-28T09:30:11.902138+00:00 [queued]>
[2024-02-28 09:30:55,422] {taskinstance.py:903} INFO - Dependencies all met for <TaskInstance: email_teste.send_email 2024-02-28T09:30:11.902138+00:00 [queued]>
[2024-02-28 09:30:55,423] {taskinstance.py:1095} INFO - 
--------------------------------------------------------------------------------
[2024-02-28 09:30:55,423] {taskinstance.py:1096} INFO - Starting attempt 2 of 2
[2024-02-28 09:30:55,423] {taskinstance.py:1097} INFO - 
--------------------------------------------------------------------------------
[2024-02-28 09:30:55,457] {taskinstance.py:1115} INFO - Executing <Task(EmailOperator): send_email> on 2024-02-28T09:30:11.902138+00:00
[2024-02-28 09:30:55,466] {standard_task_runner.py:52} INFO - Started process 98 to run task
[2024-02-28 09:30:55,472] {standard_task_runner.py:76} INFO - Running: ['***', 'tasks', 'run', 'email_teste', 'send_email', '2024-02-28T09:30:11.902138+00:00', '--job-id', '174', '--pool', 'default_pool', '--raw', '--subdir', 'DAGS_FOLDER/email.py', '--cfg-path', '/tmp/tmpnss_xi9b', '--error-file', '/tmp/tmpfb9je_kb']
[2024-02-28 09:30:55,473] {standard_task_runner.py:77} INFO - Job 174: Subtask send_email
[2024-02-28 09:30:55,561] {logging_mixin.py:109} INFO - Running <TaskInstance: email_teste.send_email 2024-02-28T09:30:11.902138+00:00 [running]> on host 7e4a9fdea90d
[2024-02-28 09:30:55,705] {taskinstance.py:1254} INFO - Exporting the following env vars:
AIRFLOW_CTX_DAG_EMAIL=jezandre_tiago@hotmail.com
AIRFLOW_CTX_DAG_OWNER=***
AIRFLOW_CTX_DAG_ID=email_teste
AIRFLOW_CTX_TASK_ID=send_email
AIRFLOW_CTX_EXECUTION_DATE=2024-02-28T09:30:11.902138+00:00
AIRFLOW_CTX_DAG_RUN_ID=manual__2024-02-28T09:30:11.902138+00:00
[2024-02-28 09:30:55,749] {logging_mixin.py:109} WARNING - /home/***/.local/lib/python3.6/site-packages/***/utils/email.py:102 PendingDeprecationWarning: Fetching SMTP credentials from configuration variables will be deprecated in a future release. Please set credentials using a connection instead.
[2024-02-28 09:30:55,750] {email.py:208} INFO - Email alerting: attempt 1
[2024-02-28 09:30:57,727] {taskinstance.py:1463} ERROR - Task failed with exception
Traceback (most recent call last):
  File "/home/airflow/.local/lib/python3.6/site-packages/airflow/models/taskinstance.py", line 1165, in _run_raw_task
    self._prepare_and_execute_task_with_callbacks(context, task)
  File "/home/airflow/.local/lib/python3.6/site-packages/airflow/models/taskinstance.py", line 1283, in _prepare_and_execute_task_with_callbacks
    result = self._execute_task(context, task_copy)
  File "/home/airflow/.local/lib/python3.6/site-packages/airflow/models/taskinstance.py", line 1313, in _execute_task
    result = task_copy.execute(context=context)
  File "/home/airflow/.local/lib/python3.6/site-packages/airflow/operators/email.py", line 88, in execute
    conn_id=self.conn_id,
  File "/home/airflow/.local/lib/python3.6/site-packages/airflow/utils/email.py", line 66, in send_email
    **kwargs,
  File "/home/airflow/.local/lib/python3.6/site-packages/airflow/utils/email.py", line 102, in send_email_smtp
    send_mime_email(e_from=smtp_mail_from, e_to=recipients, mime_msg=msg, conn_id=conn_id, dryrun=dryrun)
  File "/home/airflow/.local/lib/python3.6/site-packages/airflow/utils/email.py", line 219, in send_mime_email
    conn.login(smtp_user, smtp_password)
  File "/usr/local/lib/python3.6/smtplib.py", line 735, in login
    raise last_exception
  File "/usr/local/lib/python3.6/smtplib.py", line 726, in login
    initial_response_ok=initial_response_ok)
  File "/usr/local/lib/python3.6/smtplib.py", line 647, in auth
    raise SMTPAuthenticationError(code, resp)
smtplib.SMTPAuthenticationError: (534, b'5.7.9 Application-specific password required. For more information, go to\n5.7.9  https://support.google.com/mail/?p=InvalidSecondFactor c18-20020aa78812000000b006e4dad633e1sm7632342pfo.177 - gsmtp')
[2024-02-28 09:30:57,733] {taskinstance.py:1513} INFO - Marking task as FAILED. dag_id=email_teste, task_id=send_email, execution_date=20240228T093011, start_date=20240228T093055, end_date=20240228T093057
[2024-02-28 09:30:57,838] {email.py:208} INFO - Email alerting: attempt 1
[2024-02-28 09:31:00,314] {email.py:208} INFO - Email alerting: attempt 1
[2024-02-28 09:31:04,012] {taskinstance.py:1519} ERROR - Failed to send email to: jezandre_tiago@hotmail.com
Traceback (most recent call last):
  File "/home/airflow/.local/lib/python3.6/site-packages/airflow/models/taskinstance.py", line 1165, in _run_raw_task
    self._prepare_and_execute_task_with_callbacks(context, task)
  File "/home/airflow/.local/lib/python3.6/site-packages/airflow/models/taskinstance.py", line 1283, in _prepare_and_execute_task_with_callbacks
    result = self._execute_task(context, task_copy)
  File "/home/airflow/.local/lib/python3.6/site-packages/airflow/models/taskinstance.py", line 1313, in _execute_task
    result = task_copy.execute(context=context)
  File "/home/airflow/.local/lib/python3.6/site-packages/airflow/operators/email.py", line 88, in execute
    conn_id=self.conn_id,
  File "/home/airflow/.local/lib/python3.6/site-packages/airflow/utils/email.py", line 66, in send_email
    **kwargs,
  File "/home/airflow/.local/lib/python3.6/site-packages/airflow/utils/email.py", line 102, in send_email_smtp
    send_mime_email(e_from=smtp_mail_from, e_to=recipients, mime_msg=msg, conn_id=conn_id, dryrun=dryrun)
  File "/home/airflow/.local/lib/python3.6/site-packages/airflow/utils/email.py", line 219, in send_mime_email
    conn.login(smtp_user, smtp_password)
  File "/usr/local/lib/python3.6/smtplib.py", line 735, in login
    raise last_exception
  File "/usr/local/lib/python3.6/smtplib.py", line 726, in login
    initial_response_ok=initial_response_ok)
  File "/usr/local/lib/python3.6/smtplib.py", line 647, in auth
    raise SMTPAuthenticationError(code, resp)
smtplib.SMTPAuthenticationError: (534, b'5.7.9 Application-specific password required. For more information, go to\n5.7.9  https://support.google.com/mail/?p=InvalidSecondFactor c18-20020aa78812000000b006e4dad633e1sm7632342pfo.177 - gsmtp')

During handling of the above exception, another exception occurred:

Traceback (most recent call last):
  File "/home/airflow/.local/lib/python3.6/site-packages/airflow/models/taskinstance.py", line 1858, in email_alert
    send_email(self.task.email, subject, html_content)
  File "/home/airflow/.local/lib/python3.6/site-packages/airflow/utils/email.py", line 66, in send_email
    **kwargs,
  File "/home/airflow/.local/lib/python3.6/site-packages/airflow/utils/email.py", line 102, in send_email_smtp
    send_mime_email(e_from=smtp_mail_from, e_to=recipients, mime_msg=msg, conn_id=conn_id, dryrun=dryrun)
  File "/home/airflow/.local/lib/python3.6/site-packages/airflow/utils/email.py", line 219, in send_mime_email
    conn.login(smtp_user, smtp_password)
  File "/usr/local/lib/python3.6/smtplib.py", line 735, in login
    raise last_exception
  File "/usr/local/lib/python3.6/smtplib.py", line 726, in login
    initial_response_ok=initial_response_ok)
  File "/usr/local/lib/python3.6/smtplib.py", line 647, in auth
    raise SMTPAuthenticationError(code, resp)
smtplib.SMTPAuthenticationError: (534, b'5.7.9 Application-specific password required. For more information, go to\n5.7.9  https://support.google.com/mail/?p=InvalidSecondFactor j4-20020a170902690400b001db55b5d68bsm2860010plk.69 - gsmtp')

During handling of the above exception, another exception occurred:

Traceback (most recent call last):
  File "/home/airflow/.local/lib/python3.6/site-packages/airflow/models/taskinstance.py", line 1517, in handle_failure
    self.email_alert(error)
  File "/home/airflow/.local/lib/python3.6/site-packages/airflow/models/taskinstance.py", line 1860, in email_alert
    send_email(self.task.email, subject, html_content_err)
  File "/home/airflow/.local/lib/python3.6/site-packages/airflow/utils/email.py", line 66, in send_email
    **kwargs,
  File "/home/airflow/.local/lib/python3.6/site-packages/airflow/utils/email.py", line 102, in send_email_smtp
    send_mime_email(e_from=smtp_mail_from, e_to=recipients, mime_msg=msg, conn_id=conn_id, dryrun=dryrun)
  File "/home/airflow/.local/lib/python3.6/site-packages/airflow/utils/email.py", line 219, in send_mime_email
    conn.login(smtp_user, smtp_password)
  File "/usr/local/lib/python3.6/smtplib.py", line 735, in login
    raise last_exception
  File "/usr/local/lib/python3.6/smtplib.py", line 726, in login
    initial_response_ok=initial_response_ok)
  File "/usr/local/lib/python3.6/smtplib.py", line 647, in auth
    raise SMTPAuthenticationError(code, resp)
smtplib.SMTPAuthenticationError: (534, b'5.7.9 Application-specific password required. For more information, go to\n5.7.9  https://support.google.com/mail/?p=InvalidSecondFactor o13-20020a170903008d00b001dc1088357asm2875658pld.1 - gsmtp')
[2024-02-28 09:31:04,078] {local_task_job.py:151} INFO - Task exited with return code 1
[2024-02-28 09:31:04,127] {local_task_job.py:261} INFO - 0 downstream tasks scheduled from follow-on schedule check
