[2024-03-01 09:39:46,688] {taskinstance.py:903} INFO - Dependencies all met for <TaskInstance: pythonoperator.t1 2024-03-01T09:39:43.585687+00:00 [queued]>
[2024-03-01 09:39:46,722] {taskinstance.py:903} INFO - Dependencies all met for <TaskInstance: pythonoperator.t1 2024-03-01T09:39:43.585687+00:00 [queued]>
[2024-03-01 09:39:46,722] {taskinstance.py:1095} INFO - 
--------------------------------------------------------------------------------
[2024-03-01 09:39:46,722] {taskinstance.py:1096} INFO - Starting attempt 1 of 1
[2024-03-01 09:39:46,723] {taskinstance.py:1097} INFO - 
--------------------------------------------------------------------------------
[2024-03-01 09:39:46,738] {taskinstance.py:1115} INFO - Executing <Task(PythonOperator): t1> on 2024-03-01T09:39:43.585687+00:00
[2024-03-01 09:39:46,750] {standard_task_runner.py:52} INFO - Started process 140 to run task
[2024-03-01 09:39:46,763] {standard_task_runner.py:76} INFO - Running: ['***', 'tasks', 'run', 'pythonoperator', 't1', '2024-03-01T09:39:43.585687+00:00', '--job-id', '271', '--pool', 'default_pool', '--raw', '--subdir', 'DAGS_FOLDER/pythonoperator.py', '--cfg-path', '/tmp/tmpooxa4r1r', '--error-file', '/tmp/tmpeo7o02he']
[2024-03-01 09:39:46,764] {standard_task_runner.py:77} INFO - Job 271: Subtask t1
[2024-03-01 09:39:46,900] {logging_mixin.py:109} INFO - Running <TaskInstance: pythonoperator.t1 2024-03-01T09:39:43.585687+00:00 [running]> on host b6da4fb5c714
[2024-03-01 09:39:47,027] {taskinstance.py:1254} INFO - Exporting the following env vars:
AIRFLOW_CTX_DAG_OWNER=***
AIRFLOW_CTX_DAG_ID=pythonoperator
AIRFLOW_CTX_TASK_ID=t1
AIRFLOW_CTX_EXECUTION_DATE=2024-03-01T09:39:43.585687+00:00
AIRFLOW_CTX_DAG_RUN_ID=manual__2024-03-01T09:39:43.585687+00:00
[2024-03-01 09:39:47,158] {taskinstance.py:1463} ERROR - Task failed with exception
Traceback (most recent call last):
  File "/home/airflow/.local/lib/python3.6/site-packages/pandas/core/indexes/base.py", line 2898, in get_loc
    return self._engine.get_loc(casted_key)
  File "pandas/_libs/index.pyx", line 70, in pandas._libs.index.IndexEngine.get_loc
  File "pandas/_libs/index.pyx", line 101, in pandas._libs.index.IndexEngine.get_loc
  File "pandas/_libs/hashtable_class_helper.pxi", line 1675, in pandas._libs.hashtable.PyObjectHashTable.get_item
  File "pandas/_libs/hashtable_class_helper.pxi", line 1683, in pandas._libs.hashtable.PyObjectHashTable.get_item
KeyError: 'idade'

The above exception was the direct cause of the following exception:

Traceback (most recent call last):
  File "/home/airflow/.local/lib/python3.6/site-packages/airflow/models/taskinstance.py", line 1165, in _run_raw_task
    self._prepare_and_execute_task_with_callbacks(context, task)
  File "/home/airflow/.local/lib/python3.6/site-packages/airflow/models/taskinstance.py", line 1283, in _prepare_and_execute_task_with_callbacks
    result = self._execute_task(context, task_copy)
  File "/home/airflow/.local/lib/python3.6/site-packages/airflow/models/taskinstance.py", line 1313, in _execute_task
    result = task_copy.execute(context=context)
  File "/home/airflow/.local/lib/python3.6/site-packages/airflow/operators/python.py", line 150, in execute
    return_value = self.execute_callable()
  File "/home/airflow/.local/lib/python3.6/site-packages/airflow/operators/python.py", line 161, in execute_callable
    return self.python_callable(*self.op_args, **self.op_kwargs)
  File "/opt/airflow/dags/pythonoperator.py", line 34, in data_cleaner
    dataset.loc[(dataset['Idade']<0)|(dataset['idade']>120), 'Idade'] = mediana
  File "/home/airflow/.local/lib/python3.6/site-packages/pandas/core/frame.py", line 2906, in __getitem__
    indexer = self.columns.get_loc(key)
  File "/home/airflow/.local/lib/python3.6/site-packages/pandas/core/indexes/base.py", line 2900, in get_loc
    raise KeyError(key) from err
KeyError: 'idade'
[2024-03-01 09:39:47,179] {taskinstance.py:1513} INFO - Marking task as FAILED. dag_id=pythonoperator, task_id=t1, execution_date=20240301T093943, start_date=20240301T093946, end_date=20240301T093947
[2024-03-01 09:39:47,259] {local_task_job.py:151} INFO - Task exited with return code 1
[2024-03-01 09:39:47,315] {local_task_job.py:261} INFO - 0 downstream tasks scheduled from follow-on schedule check
