[2024-02-28 09:26:48,763] {taskinstance.py:903} INFO - Dependencies all met for <TaskInstance: email_teste.send_email 2024-02-28T09:26:08.840705+00:00 [queued]>
[2024-02-28 09:26:48,807] {taskinstance.py:903} INFO - Dependencies all met for <TaskInstance: email_teste.send_email 2024-02-28T09:26:08.840705+00:00 [queued]>
[2024-02-28 09:26:48,808] {taskinstance.py:1095} INFO - 
--------------------------------------------------------------------------------
[2024-02-28 09:26:48,808] {taskinstance.py:1096} INFO - Starting attempt 2 of 2
[2024-02-28 09:26:48,808] {taskinstance.py:1097} INFO - 
--------------------------------------------------------------------------------
[2024-02-28 09:26:48,847] {taskinstance.py:1115} INFO - Executing <Task(EmailOperator): send_email> on 2024-02-28T09:26:08.840705+00:00
[2024-02-28 09:26:48,867] {standard_task_runner.py:76} INFO - Running: ['***', 'tasks', 'run', 'email_teste', 'send_email', '2024-02-28T09:26:08.840705+00:00', '--job-id', '167', '--pool', 'default_pool', '--raw', '--subdir', 'DAGS_FOLDER/email.py', '--cfg-path', '/tmp/tmpqlgu_c0q', '--error-file', '/tmp/tmpaq3ucr1v']
[2024-02-28 09:26:48,859] {standard_task_runner.py:52} INFO - Started process 79 to run task
[2024-02-28 09:26:48,870] {standard_task_runner.py:77} INFO - Job 167: Subtask send_email
[2024-02-28 09:26:49,027] {logging_mixin.py:109} INFO - Running <TaskInstance: email_teste.send_email 2024-02-28T09:26:08.840705+00:00 [running]> on host 7e4a9fdea90d
[2024-02-28 09:26:49,220] {taskinstance.py:1254} INFO - Exporting the following env vars:
AIRFLOW_CTX_DAG_EMAIL=jezandre_tiago@hotmail.com
AIRFLOW_CTX_DAG_OWNER=***
AIRFLOW_CTX_DAG_ID=email_teste
AIRFLOW_CTX_TASK_ID=send_email
AIRFLOW_CTX_EXECUTION_DATE=2024-02-28T09:26:08.840705+00:00
AIRFLOW_CTX_DAG_RUN_ID=manual__2024-02-28T09:26:08.840705+00:00
[2024-02-28 09:26:49,292] {logging_mixin.py:109} WARNING - /home/***/.local/lib/python3.6/site-packages/***/utils/email.py:102 PendingDeprecationWarning: Fetching SMTP credentials from configuration variables will be deprecated in a future release. Please set credentials using a connection instead.
[2024-02-28 09:26:49,293] {email.py:208} INFO - Email alerting: attempt 1
[2024-02-28 09:26:52,763] {taskinstance.py:1463} ERROR - Task failed with exception
Traceback (most recent call last):
  File "/home/airflow/.local/lib/python3.6/site-packages/airflow/models/taskinstance.py", line 1165, in _run_raw_task
    self._prepare_and_execute_task_with_callbacks(context, task)
  File "/home/airflow/.local/lib/python3.6/site-packages/airflow/models/taskinstance.py", line 1283, in _prepare_and_execute_task_with_callbacks
    result = self._execute_task(context, task_copy)
  File "/home/airflow/.local/lib/python3.6/site-packages/airflow/models/taskinstance.py", line 1313, in _execute_task
    result = task_copy.execute(context=context)
  File "/home/airflow/.local/lib/python3.6/site-packages/airflow/operators/email.py", line 88, in execute
    conn_id=self.conn_id,
  File "/home/airflow/.local/lib/python3.6/site-packages/airflow/utils/email.py", line 66, in send_email
    **kwargs,
  File "/home/airflow/.local/lib/python3.6/site-packages/airflow/utils/email.py", line 102, in send_email_smtp
    send_mime_email(e_from=smtp_mail_from, e_to=recipients, mime_msg=msg, conn_id=conn_id, dryrun=dryrun)
  File "/home/airflow/.local/lib/python3.6/site-packages/airflow/utils/email.py", line 219, in send_mime_email
    conn.login(smtp_user, smtp_password)
  File "/usr/local/lib/python3.6/smtplib.py", line 735, in login
    raise last_exception
  File "/usr/local/lib/python3.6/smtplib.py", line 726, in login
    initial_response_ok=initial_response_ok)
  File "/usr/local/lib/python3.6/smtplib.py", line 647, in auth
    raise SMTPAuthenticationError(code, resp)
smtplib.SMTPAuthenticationError: (534, b'5.7.9 Application-specific password required. For more information, go to\n5.7.9  https://support.google.com/mail/?p=InvalidSecondFactor v3-20020a17090331c300b001dcb063349csm2887468ple.150 - gsmtp')
[2024-02-28 09:26:52,768] {taskinstance.py:1513} INFO - Marking task as FAILED. dag_id=email_teste, task_id=send_email, execution_date=20240228T092608, start_date=20240228T092648, end_date=20240228T092652
[2024-02-28 09:26:52,835] {email.py:208} INFO - Email alerting: attempt 1
[2024-02-28 09:26:55,312] {email.py:208} INFO - Email alerting: attempt 1
[2024-02-28 09:27:00,372] {taskinstance.py:1519} ERROR - Failed to send email to: jezandre_tiago@hotmail.com
Traceback (most recent call last):
  File "/home/airflow/.local/lib/python3.6/site-packages/airflow/models/taskinstance.py", line 1165, in _run_raw_task
    self._prepare_and_execute_task_with_callbacks(context, task)
  File "/home/airflow/.local/lib/python3.6/site-packages/airflow/models/taskinstance.py", line 1283, in _prepare_and_execute_task_with_callbacks
    result = self._execute_task(context, task_copy)
  File "/home/airflow/.local/lib/python3.6/site-packages/airflow/models/taskinstance.py", line 1313, in _execute_task
    result = task_copy.execute(context=context)
  File "/home/airflow/.local/lib/python3.6/site-packages/airflow/operators/email.py", line 88, in execute
    conn_id=self.conn_id,
  File "/home/airflow/.local/lib/python3.6/site-packages/airflow/utils/email.py", line 66, in send_email
    **kwargs,
  File "/home/airflow/.local/lib/python3.6/site-packages/airflow/utils/email.py", line 102, in send_email_smtp
    send_mime_email(e_from=smtp_mail_from, e_to=recipients, mime_msg=msg, conn_id=conn_id, dryrun=dryrun)
  File "/home/airflow/.local/lib/python3.6/site-packages/airflow/utils/email.py", line 219, in send_mime_email
    conn.login(smtp_user, smtp_password)
  File "/usr/local/lib/python3.6/smtplib.py", line 735, in login
    raise last_exception
  File "/usr/local/lib/python3.6/smtplib.py", line 726, in login
    initial_response_ok=initial_response_ok)
  File "/usr/local/lib/python3.6/smtplib.py", line 647, in auth
    raise SMTPAuthenticationError(code, resp)
smtplib.SMTPAuthenticationError: (534, b'5.7.9 Application-specific password required. For more information, go to\n5.7.9  https://support.google.com/mail/?p=InvalidSecondFactor v3-20020a17090331c300b001dcb063349csm2887468ple.150 - gsmtp')

During handling of the above exception, another exception occurred:

Traceback (most recent call last):
  File "/home/airflow/.local/lib/python3.6/site-packages/airflow/models/taskinstance.py", line 1858, in email_alert
    send_email(self.task.email, subject, html_content)
  File "/home/airflow/.local/lib/python3.6/site-packages/airflow/utils/email.py", line 66, in send_email
    **kwargs,
  File "/home/airflow/.local/lib/python3.6/site-packages/airflow/utils/email.py", line 102, in send_email_smtp
    send_mime_email(e_from=smtp_mail_from, e_to=recipients, mime_msg=msg, conn_id=conn_id, dryrun=dryrun)
  File "/home/airflow/.local/lib/python3.6/site-packages/airflow/utils/email.py", line 219, in send_mime_email
    conn.login(smtp_user, smtp_password)
  File "/usr/local/lib/python3.6/smtplib.py", line 735, in login
    raise last_exception
  File "/usr/local/lib/python3.6/smtplib.py", line 726, in login
    initial_response_ok=initial_response_ok)
  File "/usr/local/lib/python3.6/smtplib.py", line 647, in auth
    raise SMTPAuthenticationError(code, resp)
smtplib.SMTPAuthenticationError: (534, b'5.7.9 Application-specific password required. For more information, go to\n5.7.9  https://support.google.com/mail/?p=InvalidSecondFactor u19-20020aa78493000000b006e5571be110sm1535592pfn.214 - gsmtp')

During handling of the above exception, another exception occurred:

Traceback (most recent call last):
  File "/home/airflow/.local/lib/python3.6/site-packages/airflow/models/taskinstance.py", line 1517, in handle_failure
    self.email_alert(error)
  File "/home/airflow/.local/lib/python3.6/site-packages/airflow/models/taskinstance.py", line 1860, in email_alert
    send_email(self.task.email, subject, html_content_err)
  File "/home/airflow/.local/lib/python3.6/site-packages/airflow/utils/email.py", line 66, in send_email
    **kwargs,
  File "/home/airflow/.local/lib/python3.6/site-packages/airflow/utils/email.py", line 102, in send_email_smtp
    send_mime_email(e_from=smtp_mail_from, e_to=recipients, mime_msg=msg, conn_id=conn_id, dryrun=dryrun)
  File "/home/airflow/.local/lib/python3.6/site-packages/airflow/utils/email.py", line 219, in send_mime_email
    conn.login(smtp_user, smtp_password)
  File "/usr/local/lib/python3.6/smtplib.py", line 735, in login
    raise last_exception
  File "/usr/local/lib/python3.6/smtplib.py", line 726, in login
    initial_response_ok=initial_response_ok)
  File "/usr/local/lib/python3.6/smtplib.py", line 647, in auth
    raise SMTPAuthenticationError(code, resp)
smtplib.SMTPAuthenticationError: (534, b'5.7.9 Application-specific password required. For more information, go to\n5.7.9  https://support.google.com/mail/?p=InvalidSecondFactor st3-20020a17090b1fc300b00299ef19177dsm1108344pjb.8 - gsmtp')
[2024-02-28 09:27:00,436] {local_task_job.py:151} INFO - Task exited with return code 1
[2024-02-28 09:27:00,485] {local_task_job.py:261} INFO - 0 downstream tasks scheduled from follow-on schedule check
